Workbook
Name BaseArmour: BaseStats!$D:$D
Name ArmourGain: BaseStats!$E:$E
Name basename: BaseStats!$A:$A
Name HP: Combat!$C:$C
Name Unit: Combat!$A:$A
Name Level: Combat!$B:$B
Name BaseHP: BaseStats!$B:$B
Name baseenrage: BaseStats!$J:$J
Name pengain: BaseStats!$I:$I
Name ArmourPen: Combat!$F:$F
Name HPGain: BaseStats!$C:$C
Name DMG: Combat!$E:$E
Name enragegain: BaseStats!$K:$K
Name damageGain: BaseStats!$G:$G
Name Enrage: Combat!$G:$G
Name Armour: Combat!$D:$D
Name BaseDMG: BaseStats!$F:$F
Name Basepen: BaseStats!$H:$H

Sheet Combat Simulator
A1: Winner | D1: Select 1st Unit | E1: Set 1st unit level
A2: =Combat!P2 -> Berserker | D2: Berserker | E2: 2
D3: Select 2nd Unit | E3: Set 2nd unit level
D4: Archer
A7: Select a Unit from the drop down and set it's level. If no level is set the level will automatically default to 1

Sheet ExportTable
A1: UnitID | B1: FlavorName | C1: Tier | D1: Requirement1 | E1: Requirement2 | F1: Requirement3 | G1: Cost_Gold | H1: Cost_Wood | I1: Cost_Metal | J1: TrainingTime | K1: HealCost_Gold | L1: HealCost_Wood | M1: HealCost_Metal | N1: HealTime | O1: CommandSize | P1: UnitType | Q1: HitPoints | R1: Armor | S1: Damage | T1: ArmorPiercing
A2: =Econ!A2&if(Econ!B2<10,"_0"&Econ!B2,"_"&Econ!B2) -> Archer_01 | B2: ="T"&Econ!B2&" "&Econ!A2 -> T1 Archer | C2: =Econ!B2 -> 1 | G2: =Econ!L2 | H2: =Econ!M2 -> 10 | I2: =Econ!N2 | J2: =Econ!O2 -> 25 | K2: =Econ!P2 -> 0 | L2: =Econ!Q2 -> 2.5 | M2: =Econ!R2 -> 0 | N2: =Econ!S2 -> 6.25 | O2: =Econ!T2 -> 1 | P2: =Econ!A2 -> Archer | Q2: =Econ!C2 -> 150 | R2: =Econ!E2 -> 5 | S2: =Econ!G2 -> 100 | T2: =Econ!I2 -> 10
A3: =Econ!A3&if(Econ!B3<10,"_0"&Econ!B3,"_"&Econ!B3) -> Archer_02 | B3: ="T"&Econ!B3&" "&Econ!A3 -> T2 Archer | C3: =Econ!B3 -> 2 | G3: =Econ!L3 | H3: =Econ!M3 -> 13 | I3: =Econ!N3 | J3: =Econ!O3 -> 27 | K3: =Econ!P3 -> 0 | L3: =Econ!Q3 -> 3.25 | M3: =Econ!R3 -> 0 | N3: =Econ!S3 -> 6.75 | O3: =Econ!T3 -> 1 | P3: =Econ!A3 -> Archer | Q3: =Econ!C3 -> 157.5 | R3: =Econ!E3 -> 5.1 | S3: =Econ!G3 -> 105 | T3: =Econ!I3 -> 10.2
A4: =Econ!A4&if(Econ!B4<10,"_0"&Econ!B4,"_"&Econ!B4) -> Archer_03 | B4: ="T"&Econ!B4&" "&Econ!A4 -> T3 Archer | C4: =Econ!B4 -> 3 | G4: =Econ!L4 | H4: =Econ!M4 -> 17 | I4: =Econ!N4 | J4: =Econ!O4 -> 30 | K4: =Econ!P4 -> 0 | L4: =Econ!Q4 -> 4.25 | M4: =Econ!R4 -> 0 | N4: =Econ!S4 -> 7.5 | O4: =Econ!T4 -> 1 | P4: =Econ!A4 -> Archer | Q4: =Econ!C4 -> 165.375 | R4: =Econ!E4 -> 5.202 | S4: =Econ!G4 -> 110.25 | T4: =Econ!I4 -> 10.404
A5: =Econ!A5&if(Econ!B5<10,"_0"&Econ!B5,"_"&Econ!B5) -> Archer_04 | B5: ="T"&Econ!B5&" "&Econ!A5 -> T4 Archer | C5: =Econ!B5 -> 4 | G5: =Econ!L5 | H5: =Econ!M5 -> 22 | I5: =Econ!N5 | J5: =Econ!O5 -> 33 | K5: =Econ!P5 -> 0 | L5: =Econ!Q5 -> 5.5 | M5: =Econ!R5 -> 0 | N5: =Econ!S5 -> 8.25 | O5: =Econ!T5 -> 1 | P5: =Econ!A5 -> Archer | Q5: =Econ!C5 -> 173.64375 | R5: =Econ!E5 -> 5.30604 | S5: =Econ!G5 -> 115.7625 | T5: =Econ!I5 -> 10.61208
A6: =Econ!A6&if(Econ!B6<10,"_0"&Econ!B6,"_"&Econ!B6) -> Archer_05 | B6: ="T"&Econ!B6&" "&Econ!A6 -> T5 Archer | C6: =Econ!B6 -> 5 | G6: =Econ!L6 | H6: =Econ!M6 -> 28 | I6: =Econ!N6 | J6: =Econ!O6 -> 36 | K6: =Econ!P6 -> 0 | L6: =Econ!Q6 -> 7 | M6: =Econ!R6 -> 0 | N6: =Econ!S6 -> 9 | O6: =Econ!T6 -> 2 | P6: =Econ!A6 -> Archer | Q6: =Econ!C6 -> 182.32594 | R6: =Econ!E6 -> 5.4121608 | S6: =Econ!G6 -> 121.55062 | T6: =Econ!I6 -> 10.824322
A7: =Econ!A7&if(Econ!B7<10,"_0"&Econ!B7,"_"&Econ!B7) -> Archer_06 | B7: ="T"&Econ!B7&" "&Econ!A7 -> T6 Archer | C7: =Econ!B7 -> 6 | G7: =Econ!L7 | H7: =Econ!M7 -> 35 | I7: =Econ!N7 | J7: =Econ!O7 -> 40 | K7: =Econ!P7 -> 0 | L7: =Econ!Q7 -> 8.75 | M7: =Econ!R7 -> 0 | N7: =Econ!S7 -> 10 | O7: =Econ!T7 -> 2 | P7: =Econ!A7 -> Archer | Q7: =Econ!C7 -> 191.44223 | R7: =Econ!E7 -> 5.520404 | S7: =Econ!G7 -> 127.62816 | T7: =Econ!I7 -> 11.040808
A8: =Econ!A8&if(Econ!B8<10,"_0"&Econ!B8,"_"&Econ!B8) -> Archer_07 | B8: ="T"&Econ!B8&" "&Econ!A8 -> T7 Archer | C8: =Econ!B8 -> 7 | G8: =Econ!L8 | H8: =Econ!M8 -> 43 | I8: =Econ!N8 | J8: =Econ!O8 -> 44 | K8: =Econ!P8 -> 0 | L8: =Econ!Q8 -> 10.75 | M8: =Econ!R8 -> 0 | N8: =Econ!S8 -> 11 | O8: =Econ!T8 -> 2 | P8: =Econ!A8 -> Archer | Q8: =Econ!C8 -> 201.01435 | R8: =Econ!E8 -> 5.6308121 | S8: =Econ!G8 -> 134.00956 | T8: =Econ!I8 -> 11.261624
A9: =Econ!A9&if(Econ!B9<10,"_0"&Econ!B9,"_"&Econ!B9) -> Archer_08 | B9: ="T"&Econ!B9&" "&Econ!A9 -> T8 Archer | C9: =Econ!B9 -> 8 | G9: =Econ!L9 | H9: =Econ!M9 -> 51 | I9: =Econ!N9 | J9: =Econ!O9 -> 49 | K9: =Econ!P9 -> 0 | L9: =Econ!Q9 -> 12.75 | M9: =Econ!R9 -> 0 | N9: =Econ!S9 -> 12.25 | O9: =Econ!T9 -> 2 | P9: =Econ!A9 -> Archer | Q9: =Econ!C9 -> 211.06506 | R9: =Econ!E9 -> 5.7434283 | S9: =Econ!G9 -> 140.71004 | T9: =Econ!I9 -> 11.486857
A10: =Econ!A10&if(Econ!B10<10,"_0"&Econ!B10,"_"&Econ!B10) -> Archer_09 | B10: ="T"&Econ!B10&" "&Econ!A10 -> T9 Archer | C10: =Econ!B10 -> 9 | G10: =Econ!L10 | H10: =Econ!M10 -> 60 | I10: =Econ!N10 | J10: =Econ!O10 -> 54 | K10: =Econ!P10 -> 0 | L10: =Econ!Q10 -> 15 | M10: =Econ!R10 -> 0 | N10: =Econ!S10 -> 13.5 | O10: =Econ!T10 -> 2 | P10: =Econ!A10 -> Archer | Q10: =Econ!C10 -> 221.61832 | R10: =Econ!E10 -> 5.8582969 | S10: =Econ!G10 -> 147.74554 | T10: =Econ!I10 -> 11.716594
A11: =Econ!A11&if(Econ!B11<10,"_0"&Econ!B11,"_"&Econ!B11) -> Archer_10 | B11: ="T"&Econ!B11&" "&Econ!A11 -> T10 Archer | C11: =Econ!B11 -> 10 | G11: =Econ!L11 | H11: =Econ!M11 -> 70 | I11: =Econ!N11 | J11: =Econ!O11 -> 59 | K11: =Econ!P11 -> 0 | L11: =Econ!Q11 -> 17.5 | M11: =Econ!R11 -> 0 | N11: =Econ!S11 -> 14.75 | O11: =Econ!T11 -> 2 | P11: =Econ!A11 -> Archer | Q11: =Econ!C11 -> 232.69923 | R11: =Econ!E11 -> 5.9754628 | S11: =Econ!G11 -> 155.13282 | T11: =Econ!I11 -> 11.950926
A12: =Econ!A12&if(Econ!B12<10,"_0"&Econ!B12,"_"&Econ!B12) -> Archer_11 | B12: ="T"&Econ!B12&" "&Econ!A12 -> T11 Archer | C12: =Econ!B12 -> 11 | G12: =Econ!L12 | H12: =Econ!M12 -> 80 | I12: =Econ!N12 | J12: =Econ!O12 -> 65 | K12: =Econ!P12 -> 0 | L12: =Econ!Q12 -> 20 | M12: =Econ!R12 -> 0 | N12: =Econ!S12 -> 16.25 | O12: =Econ!T12 -> 2 | P12: =Econ!A12 -> Archer | Q12: =Econ!C12 -> 244.33419 | R12: =Econ!E12 -> 6.0949721 | S12: =Econ!G12 -> 162.88946 | T12: =Econ!I12 -> 12.189944
A13: =Econ!A13&if(Econ!B13<10,"_0"&Econ!B13,"_"&Econ!B13) -> Archer_12 | B13: ="T"&Econ!B13&" "&Econ!A13 -> T12 Archer | C13: =Econ!B13 -> 12 | G13: =Econ!L13 | H13: =Econ!M13 -> 91 | I13: =Econ!N13 | J13: =Econ!O13 -> 71 | K13: =Econ!P13 -> 0 | L13: =Econ!Q13 -> 22.75 | M13: =Econ!R13 -> 0 | N13: =Econ!S13 -> 17.75 | O13: =Econ!T13 -> 2 | P13: =Econ!A13 -> Archer | Q13: =Econ!C13 -> 256.5509 | R13: =Econ!E13 -> 6.2168715 | S13: =Econ!G13 -> 171.03394 | T13: =Econ!I13 -> 12.433743
... A901: =Econ!A901&if(Econ!B901<10,"_0"&Econ!B901,"_"&Econ!B901) -> Knight_300 | B901: ="T"&Econ!B901&" "&Econ!A901 -> T300 Knight | C901: =Econ!B901 -> 300 | G901: =Econ!L901 | H901: =Econ!M901 -> 56230 | I901: =Econ!N901 -> 9744 | J901: =Econ!O901 -> 9865 | K901: =Econ!P901 -> 0 | L901: =Econ!Q901 -> 14057.5 | M901: =Econ!R901 -> 2436 | N901: =Econ!S901 -> 2466.25 | O901: =Econ!T901 -> 31 | P901: =Econ!A901 -> Knight | Q901: =Econ!C901 -> 7.5799871e+08 | R901: =Econ!E901 -> 16775.052 | S901: =Econ!G901 -> 97456977 | T901: =Econ!I901 -> 0

Sheet BaseStats
A1: Name | B1: HP | C1: Level Gains | D1: Armour | E1: Level Gains | F1: DMG | G1: Level Gains | H1: ArmourPen | I1: Level Gains | J1: Enrage | K1: Level Gains | L1: Level Gains | M1: HP
A2: Knight | B2: 350 | C2: 0.05 | D2: 45 | E2: 0.02 | F2: 45 | G2: 0.05 | H2: 0 | I2: 0 | J2: 0 | K2: 0 | L2: HP | M2: 0.1
A3: Archer | B3: 150 | C3: 0.05 | D3: 5 | E3: 0.02 | F3: 100 | G3: 0.05 | H3: 10 | I3: 0.02 | J3: 0 | K3: 0 | L3: DMG | M3: 0.1
A4: Pikeman | B4: 300 | C4: 0.05 | D4: 10 | E4: 0.02 | F4: 45 | G4: 0.05 | H4: 45 | I4: 0.02 | J4: 0 | K4: 0 | L4: Armour | M4: 0.05
A5: Berserker | B5: 280 | C5: 0.05 | D5: 12 | E5: 0.02 | F5: 40 | G5: 0.05 | H5: 10 | I5: 0.02 | J5: 0.1 | K5: 0 | L5: ArmourPen | M5: 0.04
L6: Enrage | M6: 0.08

Sheet Combat
A1: UnitA | B1: Level | C1: HP | D1: Armour | E1: DMG | F1: ArmourPen | G1: Enrage | H1: Round | I1: UnitA | J1: Hp Left | K1: effective DMG | L1: Unitb | M1: Hp Left | N1: effective DMG | P1: winner
A2: ='Combat Simulator'!D2 -> Berserker | B2: =IF('Combat Simulator'!E2<1,1,'Combat Simulator'!E2) -> 2 | C2: {=index(BaseHP,match(A2,basename,0))*((1+index(HPGain,match(A2,basename,0)))^(B2-1))} -> 294 | D2: {=index(BaseArmour,match(A2,basename,0))*((1+index(ArmourGain,match(A2,basename,0)))^(B2-1))} -> 12.24 | E2: {=index(BaseDMG,match(A2,basename,0))*((1+index(damageGain,match(A2,basename,0)))^(B2-1))} -> 42 | F2: {=index(Basepen,match(A2,basename,0))*((1+index(pengain,match(A2,basename,0)))^(B2-1))} -> 10.2 | G2: {=index(baseenrage,match(A2,basename,0))*((1+index(enragegain,match(A2,basename,0)))^(B2-1))} -> 0.1 | H2: 1 | I2: =A2 -> Berserker | J2: {=index(HP,match(I2,Unit,0))} -> 294 | K2: {=max((index(DMG,match(I2,Unit,0))+(index(HP,match(I2,Unit,0))-J2)*index(Enrage,match(I2,Unit,0)))-max((index(Armour,match(L2,Unit,0))-index(ArmourPen,match(I2,Unit,0))),0))} -> 42 | L2: =A4 -> Archer | M2: {=index(HP,match(L2,Unit,0))} -> 150 | N2: {=(index(DMG,match(L2,Unit,0))+(index(HP,match(L2,Unit,0))-M2)*index(Enrage,match(L2,Unit,0)))-max((index(Armour,match(I2,Unit,0))-index(ArmourPen,match(L2,Unit,0))),0)} -> 97.76 | P2: {=IF(MATCH(TRUE, (J:J<=0) + (M:M<=0) > 0, 0) = MATCH(TRUE, J:J<=0, 0), L2, I2)} -> Berserker
A3: UnitB | H3: 2 | I3: =I2 -> Berserker | J3: =IF(J2-N2<0,0,J2-N2) -> 196.24 | K3: {=max((index(DMG,match(I3,Unit,0))+(index(HP,match(I3,Unit,0))-J3)*index(Enrage,match(I3,Unit,0)))-max((index(Armour,match(L3,Unit,0))-index(ArmourPen,match(I3,Unit,0))),0))} -> 51.776 | L3: =L2 -> Archer | M3: =IF(M2-K2<0,0,M2-K2) -> 108 | N3: {=(index(DMG,match(L3,Unit,0))+(index(HP,match(L3,Unit,0))-M3)*index(Enrage,match(L3,Unit,0)))-max((index(Armour,match(I3,Unit,0))-index(ArmourPen,match(L3,Unit,0))),0)} -> 97.76
A4: ='Combat Simulator'!D4 -> Archer | B4: =if('Combat Simulator'!E4<1,1,'Combat Simulator'!E4) -> 1 | C4: {=index(BaseHP,match(A4,basename,0))*((1+index(HPGain,match(A4,basename,0)))^(B4-1))} -> 150 | D4: {=index(BaseArmour,match(A4,basename,0))*((1+index(ArmourGain,match(A4,basename,0)))^(B4-1))} -> 5 | E4: {=index(BaseDMG,match(A4,basename,0))*((1+index(damageGain,match(A4,basename,0)))^(B4-1))} -> 100 | F4: {=index(Basepen,match(A4,basename,0))*((1+index(pengain,match(A4,basename,0)))^(B4-1))} -> 10 | G4: {=index(baseenrage,match(A4,basename,0))*((1+index(enragegain,match(A4,basename,0)))^(B4-1))} -> 0 | H4: 3 | I4: =I3 -> Berserker | J4: =IF(J3-N3<0,0,J3-N3) -> 98.48 | K4: {=max((index(DMG,match(I4,Unit,0))+(index(HP,match(I4,Unit,0))-J4)*index(Enrage,match(I4,Unit,0)))-max((index(Armour,match(L4,Unit,0))-index(ArmourPen,match(I4,Unit,0))),0))} -> 61.552 | L4: =L3 -> Archer | M4: =IF(M3-K3<0,0,M3-K3) -> 56.224 | N4: {=(index(DMG,match(L4,Unit,0))+(index(HP,match(L4,Unit,0))-M4)*index(Enrage,match(L4,Unit,0)))-max((index(Armour,match(I4,Unit,0))-index(ArmourPen,match(L4,Unit,0))),0)} -> 97.76
H5: 4 | I5: =I4 -> Berserker | J5: =IF(J4-N4<0,0,J4-N4) -> 0.72 | K5: {=max((index(DMG,match(I5,Unit,0))+(index(HP,match(I5,Unit,0))-J5)*index(Enrage,match(I5,Unit,0)))-max((index(Armour,match(L5,Unit,0))-index(ArmourPen,match(I5,Unit,0))),0))} -> 71.328 | L5: =L4 -> Archer | M5: =IF(M4-K4<0,0,M4-K4) -> 0 | N5: {=(index(DMG,match(L5,Unit,0))+(index(HP,match(L5,Unit,0))-M5)*index(Enrage,match(L5,Unit,0)))-max((index(Armour,match(I5,Unit,0))-index(ArmourPen,match(L5,Unit,0))),0)} -> 97.76
H6: 5 | I6: =I5 -> Berserker | J6: =IF(J5-N5<0,0,J5-N5) -> 0 | K6: {=max((index(DMG,match(I6,Unit,0))+(index(HP,match(I6,Unit,0))-J6)*index(Enrage,match(I6,Unit,0)))-max((index(Armour,match(L6,Unit,0))-index(ArmourPen,match(I6,Unit,0))),0))} -> 71.4 | L6: =L5 -> Archer | M6: =IF(M5-K5<0,0,M5-K5) -> 0 | N6: {=(index(DMG,match(L6,Unit,0))+(index(HP,match(L6,Unit,0))-M6)*index(Enrage,match(L6,Unit,0)))-max((index(Armour,match(I6,Unit,0))-index(ArmourPen,match(L6,Unit,0))),0)} -> 97.76
H7: 6 | I7: =I6 -> Berserker | J7: =IF(J6-N6<0,0,J6-N6) -> 0 | K7: {=max((index(DMG,match(I7,Unit,0))+(index(HP,match(I7,Unit,0))-J7)*index(Enrage,match(I7,Unit,0)))-max((index(Armour,match(L7,Unit,0))-index(ArmourPen,match(I7,Unit,0))),0))} -> 71.4 | L7: =L6 -> Archer | M7: =IF(M6-K6<0,0,M6-K6) -> 0 | N7: {=(index(DMG,match(L7,Unit,0))+(index(HP,match(L7,Unit,0))-M7)*index(Enrage,match(L7,Unit,0)))-max((index(Armour,match(I7,Unit,0))-index(ArmourPen,match(L7,Unit,0))),0)} -> 97.76
H8: 7 | I8: =I7 -> Berserker | J8: =IF(J7-N7<0,0,J7-N7) -> 0 | K8: {=max((index(DMG,match(I8,Unit,0))+(index(HP,match(I8,Unit,0))-J8)*index(Enrage,match(I8,Unit,0)))-max((index(Armour,match(L8,Unit,0))-index(ArmourPen,match(I8,Unit,0))),0))} -> 71.4 | L8: =L7 -> Archer | M8: =IF(M7-K7<0,0,M7-K7) -> 0 | N8: {=(index(DMG,match(L8,Unit,0))+(index(HP,match(L8,Unit,0))-M8)*index(Enrage,match(L8,Unit,0)))-max((index(Armour,match(I8,Unit,0))-index(ArmourPen,match(L8,Unit,0))),0)} -> 97.76
H9: 8 | I9: =I8 -> Berserker | J9: =IF(J8-N8<0,0,J8-N8) -> 0 | K9: {=max((index(DMG,match(I9,Unit,0))+(index(HP,match(I9,Unit,0))-J9)*index(Enrage,match(I9,Unit,0)))-max((index(Armour,match(L9,Unit,0))-index(ArmourPen,match(I9,Unit,0))),0))} -> 71.4 | L9: =L8 -> Archer | M9: =IF(M8-K8<0,0,M8-K8) -> 0 | N9: {=(index(DMG,match(L9,Unit,0))+(index(HP,match(L9,Unit,0))-M9)*index(Enrage,match(L9,Unit,0)))-max((index(Armour,match(I9,Unit,0))-index(ArmourPen,match(L9,Unit,0))),0)} -> 97.76
H10: 9 | I10: =I9 -> Berserker | J10: =IF(J9-N9<0,0,J9-N9) -> 0 | K10: {=max((index(DMG,match(I10,Unit,0))+(index(HP,match(I10,Unit,0))-J10)*index(Enrage,match(I10,Unit,0)))-max((index(Armour,match(L10,Unit,0))-index(ArmourPen,match(I10,Unit,0))),0))} -> 71.4 | L10: =L9 -> Archer | M10: =IF(M9-K9<0,0,M9-K9) -> 0 | N10: {=(index(DMG,match(L10,Unit,0))+(index(HP,match(L10,Unit,0))-M10)*index(Enrage,match(L10,Unit,0)))-max((index(Armour,match(I10,Unit,0))-index(ArmourPen,match(L10,Unit,0))),0)} -> 97.76
H11: 10 | I11: =I10 -> Berserker | J11: =IF(J10-N10<0,0,J10-N10) -> 0 | K11: {=max((index(DMG,match(I11,Unit,0))+(index(HP,match(I11,Unit,0))-J11)*index(Enrage,match(I11,Unit,0)))-max((index(Armour,match(L11,Unit,0))-index(ArmourPen,match(I11,Unit,0))),0))} -> 71.4 | L11: =L10 -> Archer | M11: =IF(M10-K10<0,0,M10-K10) -> 0 | N11: {=(index(DMG,match(L11,Unit,0))+(index(HP,match(L11,Unit,0))-M11)*index(Enrage,match(L11,Unit,0)))-max((index(Armour,match(I11,Unit,0))-index(ArmourPen,match(L11,Unit,0))),0)} -> 97.76
H12: 11 | I12: =I11 -> Berserker | J12: =IF(J11-N11<0,0,J11-N11) -> 0 | K12: {=max((index(DMG,match(I12,Unit,0))+(index(HP,match(I12,Unit,0))-J12)*index(Enrage,match(I12,Unit,0)))-max((index(Armour,match(L12,Unit,0))-index(ArmourPen,match(I12,Unit,0))),0))} -> 71.4 | L12: =L11 -> Archer | M12: =IF(M11-K11<0,0,M11-K11) -> 0 | N12: {=(index(DMG,match(L12,Unit,0))+(index(HP,match(L12,Unit,0))-M12)*index(Enrage,match(L12,Unit,0)))-max((index(Armour,match(I12,Unit,0))-index(ArmourPen,match(L12,Unit,0))),0)} -> 97.76
H13: 12 | I13: =I12 -> Berserker | J13: =IF(J12-N12<0,0,J12-N12) -> 0 | K13: {=max((index(DMG,match(I13,Unit,0))+(index(HP,match(I13,Unit,0))-J13)*index(Enrage,match(I13,Unit,0)))-max((index(Armour,match(L13,Unit,0))-index(ArmourPen,match(I13,Unit,0))),0))} -> 71.4 | L13: =L12 -> Archer | M13: =IF(M12-K12<0,0,M12-K12) -> 0 | N13: {=(index(DMG,match(L13,Unit,0))+(index(HP,match(L13,Unit,0))-M13)*index(Enrage,match(L13,Unit,0)))-max((index(Armour,match(I13,Unit,0))-index(ArmourPen,match(L13,Unit,0))),0)} -> 97.76
H14: 13 | I14: =I13 -> Berserker | J14: =IF(J13-N13<0,0,J13-N13) -> 0 | K14: {=max((index(DMG,match(I14,Unit,0))+(index(HP,match(I14,Unit,0))-J14)*index(Enrage,match(I14,Unit,0)))-max((index(Armour,match(L14,Unit,0))-index(ArmourPen,match(I14,Unit,0))),0))} -> 71.4 | L14: =L13 -> Archer | M14: =IF(M13-K13<0,0,M13-K13) -> 0 | N14: {=(index(DMG,match(L14,Unit,0))+(index(HP,match(L14,Unit,0))-M14)*index(Enrage,match(L14,Unit,0)))-max((index(Armour,match(I14,Unit,0))-index(ArmourPen,match(L14,Unit,0))),0)} -> 97.76
H15: 14 | I15: =I14 -> Berserker | J15: =IF(J14-N14<0,0,J14-N14) -> 0 | K15: {=max((index(DMG,match(I15,Unit,0))+(index(HP,match(I15,Unit,0))-J15)*index(Enrage,match(I15,Unit,0)))-max((index(Armour,match(L15,Unit,0))-index(ArmourPen,match(I15,Unit,0))),0))} -> 71.4 | L15: =L14 -> Archer | M15: =IF(M14-K14<0,0,M14-K14) -> 0 | N15: {=(index(DMG,match(L15,Unit,0))+(index(HP,match(L15,Unit,0))-M15)*index(Enrage,match(L15,Unit,0)))-max((index(Armour,match(I15,Unit,0))-index(ArmourPen,match(L15,Unit,0))),0)} -> 97.76
H16: 15 | I16: =I15 -> Berserker | J16: =IF(J15-N15<0,0,J15-N15) -> 0 | K16: {=max((index(DMG,match(I16,Unit,0))+(index(HP,match(I16,Unit,0))-J16)*index(Enrage,match(I16,Unit,0)))-max((index(Armour,match(L16,Unit,0))-index(ArmourPen,match(I16,Unit,0))),0))} -> 71.4 | L16: =L15 -> Archer | M16: =IF(M15-K15<0,0,M15-K15) -> 0 | N16: {=(index(DMG,match(L16,Unit,0))+(index(HP,match(L16,Unit,0))-M16)*index(Enrage,match(L16,Unit,0)))-max((index(Armour,match(I16,Unit,0))-index(ArmourPen,match(L16,Unit,0))),0)} -> 97.76
... H18: 17 | I18: =I17 -> Berserker | J18: =IF(J17-N17<0,0,J17-N17) -> 0 | K18: {=max((index(DMG,match(I18,Unit,0))+(index(HP,match(I18,Unit,0))-J18)*index(Enrage,match(I18,Unit,0)))-max((index(Armour,match(L18,Unit,0))-index(ArmourPen,match(I18,Unit,0))),0))} -> 71.4 | L18: =L17 -> Archer | M18: =IF(M17-K17<0,0,M17-K17) -> 0 | N18: {=(index(DMG,match(L18,Unit,0))+(index(HP,match(L18,Unit,0))-M18)*index(Enrage,match(L18,Unit,0)))-max((index(Armour,match(I18,Unit,0))-index(ArmourPen,match(L18,Unit,0))),0)} -> 97.76

Sheet Econ
A1: Name | B1: Level | C1: HP | D1: Level Gains | E1: Armour | F1: Level Gains | G1: DMG | H1: Level Gains | I1: ArmourPen | J1: Level Gains | K1: Enrage | L1: Cost_Gold | M1: Cost_Wood | N1: Cost_Metal | O1: Time | P1: HealCost_Gold | Q1: HealCost_Wood | R1: HealCost_Metal | S1: HealTime | T1: CommandSize | U1: Factor Gold | V1: Factor Wood | W1: Factor Metal | X1: Factor Time | Y1: Heal Multi | Z1: power gain
A2: Archer | B2: 1 | C2: 150 | D2: 0.05 | E2: 5 | F2: 0.02 | G2: 100 | H2: 0.05 | I2: 10 | J2: 0.02 | K2: 0 | M2: 10 | O2: 25 | P2: =L2*$Y$2 -> 0 | Q2: =M2*$Y$2 -> 2.5 | R2: =N2*$Y$2 -> 0 | S2: =O2*$Y$2 -> 6.25 | T2: =mround(B2/10,1)+1 -> 1 | U2: 0.7 | V2: 0.7 | W2: 0.7 | X2: 0.7 | Y2: 0.25
A3: Archer | B3: 2 | C3: =C2+D2*C2 -> 157.5 | D3: 0.05 | E3: =E2+F2*E2 -> 5.1 | F3: 0.02 | G3: =G2+H2*G2 -> 105 | H3: 0.05 | I3: =I2+J2*I2 -> 10.2 | J3: 0.02 | K3: 0 | L3: =IF(L2="", "", 1 + MROUND(IFERROR(MINIFS(OFFSET(L2, -1, 0, -$B3, 1), OFFSET(L2, -1, 0, -$B3, 1), ">0"), L2) + (LN(1 + $Z3) ^ U$2) * U$3, 1)) | M3: =IF(M2="", "", 1 + MROUND(IFERROR(MINIFS(OFFSET(M2, -1, 0, -$B3, 1), OFFSET(M2, -1, 0, -$B3, 1), ">0"), M2) + (LN(1 + $Z3) ^ V$2) * V$3, 1)) -> 13 | N3: =IF(N2="", "", 1 + MROUND(IFERROR(MINIFS(OFFSET(N2, -1, 0, -$B3, 1), OFFSET(N2, -1, 0, -$B3, 1), ">0"), N2) + (LN(1 + $Z3) ^ W$2) * W$3, 1)) | O3: =IF(O2="", "", 1 + MROUND(IFERROR(MINIFS(OFFSET(O2, -1, 0, -$B3, 1), OFFSET(O2, -1, 0, -$B3, 1), ">0"), O2) + (LN(1 + $Z3) ^ X$2) * X$3, 1)) -> 27 | P3: =L3*$Y$2 -> 0 | Q3: =M3*$Y$2 -> 3.25 | R3: =N3*$Y$2 -> 0 | S3: =O3*$Y$2 -> 6.75 | T3: =mround(B3/10,1)+1 -> 1 | U3: 250 | V3: 20 | W3: 10 | X3: 10 | Z3: =((1+average(D3,F3,H3,J3))^(B3-1)-1) -> 0.035
A4: Archer | B4: 3 | C4: =C3+D3*C3 -> 165.375 | D4: 0.05 | E4: =E3+F3*E3 -> 5.202 | F4: 0.02 | G4: =G3+H3*G3 -> 110.25 | H4: 0.05 | I4: =I3+J3*I3 -> 10.404 | J4: 0.02 | K4: 0 | L4: =IF(L3="", "", 1 + MROUND(IFERROR(MINIFS(OFFSET(L3, -1, 0, -$B4, 1), OFFSET(L3, -1, 0, -$B4, 1), ">0"), L3) + (LN(1 + $Z4) ^ U$2) * U$3, 1)) | M4: =IF(M3="", "", 1 + MROUND(IFERROR(MINIFS(OFFSET(M3, -1, 0, -$B4, 1), OFFSET(M3, -1, 0, -$B4, 1), ">0"), M3) + (LN(1 + $Z4) ^ V$2) * V$3, 1)) -> 17 | N4: =IF(N3="", "", 1 + MROUND(IFERROR(MINIFS(OFFSET(N3, -1, 0, -$B4, 1), OFFSET(N3, -1, 0, -$B4, 1), ">0"), N3) + (LN(1 + $Z4) ^ W$2) * W$3, 1)) | O4: =IF(O3="", "", 1 + MROUND(IFERROR(MINIFS(OFFSET(O3, -1, 0, -$B4, 1), OFFSET(O3, -1, 0, -$B4, 1), ">0"), O3) + (LN(1 + $Z4) ^ X$2) * X$3, 1)) -> 30 | P4: =L4*$Y$2 -> 0 | Q4: =M4*$Y$2 -> 4.25 | R4: =N4*$Y$2 -> 0 | S4: =O4*$Y$2 -> 7.5 | T4: =mround(B4/10,1)+1 -> 1 | U4: =max(L:L) -> 338508 | V4: =max(M:M) -> 58333 | W4: =max(N:N) -> 9744 | X4: =max(O:O) -> 9865 | Z4: =((1+average(D4,F4,H4,J4))^(B4-1)-1) -> 0.071225
A5: Archer | B5: 4 | C5: =C4+D4*C4 -> 173.64375 | D5: 0.05 | E5: =E4+F4*E4 -> 5.30604 | F5: 0.02 | G5: =G4+H4*G4 -> 115.7625 | H5: 0.05 | I5: =I4+J4*I4 -> 10.61208 | J5: 0.02 | K5: 0 | L5: =IF(L4="", "", 1 + MROUND(IFERROR(MINIFS(OFFSET(L4, -1, 0, -$B5, 1), OFFSET(L4, -1, 0, -$B5, 1), ">0"), L4) + (LN(1 + $Z5) ^ U$2) * U$3, 1)) | M5: =IF(M4="", "", 1 + MROUND(IFERROR(MINIFS(OFFSET(M4, -1, 0, -$B5, 1), OFFSET(M4, -1, 0, -$B5, 1), ">0"), M4) + (LN(1 + $Z5) ^ V$2) * V$3, 1)) -> 22 | N5: =IF(N4="", "", 1 + MROUND(IFERROR(MINIFS(OFFSET(N4, -1, 0, -$B5, 1), OFFSET(N4, -1, 0, -$B5, 1), ">0"), N4) + (LN(1 + $Z5) ^ W$2) * W$3, 1)) | O5: =IF(O4="", "", 1 + MROUND(IFERROR(MINIFS(OFFSET(O4, -1, 0, -$B5, 1), OFFSET(O4, -1, 0, -$B5, 1), ">0"), O4) + (LN(1 + $Z5) ^ X$2) * X$3, 1)) -> 33 | P5: =L5*$Y$2 -> 0 | Q5: =M5*$Y$2 -> 5.5 | R5: =N5*$Y$2 -> 0 | S5: =O5*$Y$2 -> 8.25 | T5: =mround(B5/10,1)+1 -> 1 | X5: =X4/3600 -> 2.7402778 | Z5: =((1+average(D5,F5,H5,J5))^(B5-1)-1) -> 0.10871788
A6: Archer | B6: 5 | C6: =C5+D5*C5 -> 182.32594 | D6: 0.05 | E6: =E5+F5*E5 -> 5.4121608 | F6: 0.02 | G6: =G5+H5*G5 -> 121.55062 | H6: 0.05 | I6: =I5+J5*I5 -> 10.824322 | J6: 0.02 | K6: 0 | L6: =IF(L5="", "", 1 + MROUND(IFERROR(MINIFS(OFFSET(L5, -1, 0, -$B6, 1), OFFSET(L5, -1, 0, -$B6, 1), ">0"), L5) + (LN(1 + $Z6) ^ U$2) * U$3, 1)) | M6: =IF(M5="", "", 1 + MROUND(IFERROR(MINIFS(OFFSET(M5, -1, 0, -$B6, 1), OFFSET(M5, -1, 0, -$B6, 1), ">0"), M5) + (LN(1 + $Z6) ^ V$2) * V$3, 1)) -> 28 | N6: =IF(N5="", "", 1 + MROUND(IFERROR(MINIFS(OFFSET(N5, -1, 0, -$B6, 1), OFFSET(N5, -1, 0, -$B6, 1), ">0"), N5) + (LN(1 + $Z6) ^ W$2) * W$3, 1)) | O6: =IF(O5="", "", 1 + MROUND(IFERROR(MINIFS(OFFSET(O5, -1, 0, -$B6, 1), OFFSET(O5, -1, 0, -$B6, 1), ">0"), O5) + (LN(1 + $Z6) ^ X$2) * X$3, 1)) -> 36 | P6: =L6*$Y$2 -> 0 | Q6: =M6*$Y$2 -> 7 | R6: =N6*$Y$2 -> 0 | S6: =O6*$Y$2 -> 9 | T6: =mround(B6/10,1)+1 -> 2 | Z6: =((1+average(D6,F6,H6,J6))^(B6-1)-1) -> 0.147523
A7: Archer | B7: 6 | C7: =C6+D6*C6 -> 191.44223 | D7: 0.05 | E7: =E6+F6*E6 -> 5.520404 | F7: 0.02 | G7: =G6+H6*G6 -> 127.62816 | H7: 0.05 | I7: =I6+J6*I6 -> 11.040808 | J7: 0.02 | K7: 0 | L7: =IF(L6="", "", 1 + MROUND(IFERROR(MINIFS(OFFSET(L6, -1, 0, -$B7, 1), OFFSET(L6, -1, 0, -$B7, 1), ">0"), L6) + (LN(1 + $Z7) ^ U$2) * U$3, 1)) | M7: =IF(M6="", "", 1 + MROUND(IFERROR(MINIFS(OFFSET(M6, -1, 0, -$B7, 1), OFFSET(M6, -1, 0, -$B7, 1), ">0"), M6) + (LN(1 + $Z7) ^ V$2) * V$3, 1)) -> 35 | N7: =IF(N6="", "", 1 + MROUND(IFERROR(MINIFS(OFFSET(N6, -1, 0, -$B7, 1), OFFSET(N6, -1, 0, -$B7, 1), ">0"), N6) + (LN(1 + $Z7) ^ W$2) * W$3, 1)) | O7: =IF(O6="", "", 1 + MROUND(IFERROR(MINIFS(OFFSET(O6, -1, 0, -$B7, 1), OFFSET(O6, -1, 0, -$B7, 1), ">0"), O6) + (LN(1 + $Z7) ^ X$2) * X$3, 1)) -> 40 | P7: =L7*$Y$2 -> 0 | Q7: =M7*$Y$2 -> 8.75 | R7: =N7*$Y$2 -> 0 | S7: =O7*$Y$2 -> 10 | T7: =mround(B7/10,1)+1 -> 2 | Z7: =((1+average(D7,F7,H7,J7))^(B7-1)-1) -> 0.18768631
A8: Archer | B8: 7 | C8: =C7+D7*C7 -> 201.01435 | D8: 0.05 | E8: =E7+F7*E7 -> 5.6308121 | F8: 0.02 | G8: =G7+H7*G7 -> 134.00956 | H8: 0.05 | I8: =I7+J7*I7 -> 11.261624 | J8: 0.02 | K8: 0 | L8: =IF(L7="", "", 1 + MROUND(IFERROR(MINIFS(OFFSET(L7, -1, 0, -$B8, 1), OFFSET(L7, -1, 0, -$B8, 1), ">0"), L7) + (LN(1 + $Z8) ^ U$2) * U$3, 1)) | M8: =IF(M7="", "", 1 + MROUND(IFERROR(MINIFS(OFFSET(M7, -1, 0, -$B8, 1), OFFSET(M7, -1, 0, -$B8, 1), ">0"), M7) + (LN(1 + $Z8) ^ V$2) * V$3, 1)) -> 43 | N8: =IF(N7="", "", 1 + MROUND(IFERROR(MINIFS(OFFSET(N7, -1, 0, -$B8, 1), OFFSET(N7, -1, 0, -$B8, 1), ">0"), N7) + (LN(1 + $Z8) ^ W$2) * W$3, 1)) | O8: =IF(O7="", "", 1 + MROUND(IFERROR(MINIFS(OFFSET(O7, -1, 0, -$B8, 1), OFFSET(O7, -1, 0, -$B8, 1), ">0"), O7) + (LN(1 + $Z8) ^ X$2) * X$3, 1)) -> 44 | P8: =L8*$Y$2 -> 0 | Q8: =M8*$Y$2 -> 10.75 | R8: =N8*$Y$2 -> 0 | S8: =O8*$Y$2 -> 11 | T8: =mround(B8/10,1)+1 -> 2 | Z8: =((1+average(D8,F8,H8,J8))^(B8-1)-1) -> 0.22925533
A9: Archer | B9: 8 | C9: =C8+D8*C8 -> 211.06506 | D9: 0.05 | E9: =E8+F8*E8 -> 5.7434283 | F9: 0.02 | G9: =G8+H8*G8 -> 140.71004 | H9: 0.05 | I9: =I8+J8*I8 -> 11.486857 | J9: 0.02 | K9: 0 | L9: =IF(L8="", "", 1 + MROUND(IFERROR(MINIFS(OFFSET(L8, -1, 0, -$B9, 1), OFFSET(L8, -1, 0, -$B9, 1), ">0"), L8) + (LN(1 + $Z9) ^ U$2) * U$3, 1)) | M9: =IF(M8="", "", 1 + MROUND(IFERROR(MINIFS(OFFSET(M8, -1, 0, -$B9, 1), OFFSET(M8, -1, 0, -$B9, 1), ">0"), M8) + (LN(1 + $Z9) ^ V$2) * V$3, 1)) -> 51 | N9: =IF(N8="", "", 1 + MROUND(IFERROR(MINIFS(OFFSET(N8, -1, 0, -$B9, 1), OFFSET(N8, -1, 0, -$B9, 1), ">0"), N8) + (LN(1 + $Z9) ^ W$2) * W$3, 1)) | O9: =IF(O8="", "", 1 + MROUND(IFERROR(MINIFS(OFFSET(O8, -1, 0, -$B9, 1), OFFSET(O8, -1, 0, -$B9, 1), ">0"), O8) + (LN(1 + $Z9) ^ X$2) * X$3, 1)) -> 49 | P9: =L9*$Y$2 -> 0 | Q9: =M9*$Y$2 -> 12.75 | R9: =N9*$Y$2 -> 0 | S9: =O9*$Y$2 -> 12.25 | T9: =mround(B9/10,1)+1 -> 2 | Z9: =((1+average(D9,F9,H9,J9))^(B9-1)-1) -> 0.27227926
A10: Archer | B10: 9 | C10: =C9+D9*C9 -> 221.61832 | D10: 0.05 | E10: =E9+F9*E9 -> 5.8582969 | F10: 0.02 | G10: =G9+H9*G9 -> 147.74554 | H10: 0.05 | I10: =I9+J9*I9 -> 11.716594 | J10: 0.02 | K10: 0 | L10: =IF(L9="", "", 1 + MROUND(IFERROR(MINIFS(OFFSET(L9, -1, 0, -$B10, 1), OFFSET(L9, -1, 0, -$B10, 1), ">0"), L9) + (LN(1 + $Z10) ^ U$2) * U$3, 1)) | M10: =IF(M9="", "", 1 + MROUND(IFERROR(MINIFS(OFFSET(M9, -1, 0, -$B10, 1), OFFSET(M9, -1, 0, -$B10, 1), ">0"), M9) + (LN(1 + $Z10) ^ V$2) * V$3, 1)) -> 60 | N10: =IF(N9="", "", 1 + MROUND(IFERROR(MINIFS(OFFSET(N9, -1, 0, -$B10, 1), OFFSET(N9, -1, 0, -$B10, 1), ">0"), N9) + (LN(1 + $Z10) ^ W$2) * W$3, 1)) | O10: =IF(O9="", "", 1 + MROUND(IFERROR(MINIFS(OFFSET(O9, -1, 0, -$B10, 1), OFFSET(O9, -1, 0, -$B10, 1), ">0"), O9) + (LN(1 + $Z10) ^ X$2) * X$3, 1)) -> 54 | P10: =L10*$Y$2 -> 0 | Q10: =M10*$Y$2 -> 15 | R10: =N10*$Y$2 -> 0 | S10: =O10*$Y$2 -> 13.5 | T10: =mround(B10/10,1)+1 -> 2 | Z10: =((1+average(D10,F10,H10,J10))^(B10-1)-1) -> 0.31680904
A11: Archer | B11: 10 | C11: =C10+D10*C10 -> 232.69923 | D11: 0.05 | E11: =E10+F10*E10 -> 5.9754628 | F11: 0.02 | G11: =G10+H10*G10 -> 155.13282 | H11: 0.05 | I11: =I10+J10*I10 -> 11.950926 | J11: 0.02 | K11: 0 | L11: =IF(L10="", "", 1 + MROUND(IFERROR(MINIFS(OFFSET(L10, -1, 0, -$B11, 1), OFFSET(L10, -1, 0, -$B11, 1), ">0"), L10) + (LN(1 + $Z11) ^ U$2) * U$3, 1)) | M11: =IF(M10="", "", 1 + MROUND(IFERROR(MINIFS(OFFSET(M10, -1, 0, -$B11, 1), OFFSET(M10, -1, 0, -$B11, 1), ">0"), M10) + (LN(1 + $Z11) ^ V$2) * V$3, 1)) -> 70 | N11: =IF(N10="", "", 1 + MROUND(IFERROR(MINIFS(OFFSET(N10, -1, 0, -$B11, 1), OFFSET(N10, -1, 0, -$B11, 1), ">0"), N10) + (LN(1 + $Z11) ^ W$2) * W$3, 1)) | O11: =IF(O10="", "", 1 + MROUND(IFERROR(MINIFS(OFFSET(O10, -1, 0, -$B11, 1), OFFSET(O10, -1, 0, -$B11, 1), ">0"), O10) + (LN(1 + $Z11) ^ X$2) * X$3, 1)) -> 59 | P11: =L11*$Y$2 -> 0 | Q11: =M11*$Y$2 -> 17.5 | R11: =N11*$Y$2 -> 0 | S11: =O11*$Y$2 -> 14.75 | T11: =mround(B11/10,1)+1 -> 2 | Z11: =((1+average(D11,F11,H11,J11))^(B11-1)-1) -> 0.36289735
A12: Archer | B12: 11 | C12: =C11+D11*C11 -> 244.33419 | D12: 0.05 | E12: =E11+F11*E11 -> 6.0949721 | F12: 0.02 | G12: =G11+H11*G11 -> 162.88946 | H12: 0.05 | I12: =I11+J11*I11 -> 12.189944 | J12: 0.02 | K12: 0 | L12: =IF(L11="", "", 1 + MROUND(IFERROR(MINIFS(OFFSET(L11, -1, 0, -$B12, 1), OFFSET(L11, -1, 0, -$B12, 1), ">0"), L11) + (LN(1 + $Z12) ^ U$2) * U$3, 1)) | M12: =IF(M11="", "", 1 + MROUND(IFERROR(MINIFS(OFFSET(M11, -1, 0, -$B12, 1), OFFSET(M11, -1, 0, -$B12, 1), ">0"), M11) + (LN(1 + $Z12) ^ V$2) * V$3, 1)) -> 80 | N12: =IF(N11="", "", 1 + MROUND(IFERROR(MINIFS(OFFSET(N11, -1, 0, -$B12, 1), OFFSET(N11, -1, 0, -$B12, 1), ">0"), N11) + (LN(1 + $Z12) ^ W$2) * W$3, 1)) | O12: =IF(O11="", "", 1 + MROUND(IFERROR(MINIFS(OFFSET(O11, -1, 0, -$B12, 1), OFFSET(O11, -1, 0, -$B12, 1), ">0"), O11) + (LN(1 + $Z12) ^ X$2) * X$3, 1)) -> 65 | P12: =L12*$Y$2 -> 0 | Q12: =M12*$Y$2 -> 20 | R12: =N12*$Y$2 -> 0 | S12: =O12*$Y$2 -> 16.25 | T12: =mround(B12/10,1)+1 -> 2 | Z12: =((1+average(D12,F12,H12,J12))^(B12-1)-1) -> 0.41059876
A13: Archer | B13: 12 | C13: =C12+D12*C12 -> 256.5509 | D13: 0.05 | E13: =E12+F12*E12 -> 6.2168715 | F13: 0.02 | G13: =G12+H12*G12 -> 171.03394 | H13: 0.05 | I13: =I12+J12*I12 -> 12.433743 | J13: 0.02 | K13: 0 | L13: =IF(L12="", "", 1 + MROUND(IFERROR(MINIFS(OFFSET(L12, -1, 0, -$B13, 1), OFFSET(L12, -1, 0, -$B13, 1), ">0"), L12) + (LN(1 + $Z13) ^ U$2) * U$3, 1)) | M13: =IF(M12="", "", 1 + MROUND(IFERROR(MINIFS(OFFSET(M12, -1, 0, -$B13, 1), OFFSET(M12, -1, 0, -$B13, 1), ">0"), M12) + (LN(1 + $Z13) ^ V$2) * V$3, 1)) -> 91 | N13: =IF(N12="", "", 1 + MROUND(IFERROR(MINIFS(OFFSET(N12, -1, 0, -$B13, 1), OFFSET(N12, -1, 0, -$B13, 1), ">0"), N12) + (LN(1 + $Z13) ^ W$2) * W$3, 1)) | O13: =IF(O12="", "", 1 + MROUND(IFERROR(MINIFS(OFFSET(O12, -1, 0, -$B13, 1), OFFSET(O12, -1, 0, -$B13, 1), ">0"), O12) + (LN(1 + $Z13) ^ X$2) * X$3, 1)) -> 71 | P13: =L13*$Y$2 -> 0 | Q13: =M13*$Y$2 -> 22.75 | R13: =N13*$Y$2 -> 0 | S13: =O13*$Y$2 -> 17.75 | T13: =mround(B13/10,1)+1 -> 2 | Z13: =((1+average(D13,F13,H13,J13))^(B13-1)-1) -> 0.45996972
A14: Archer | B14: 13 | C14: =C13+D13*C13 -> 269.37845 | D14: 0.05 | E14: =E13+F13*E13 -> 6.341209 | F14: 0.02 | G14: =G13+H13*G13 -> 179.58563 | H14: 0.05 | I14: =I13+J13*I13 -> 12.682418 | J14: 0.02 | K14: 0 | L14: =IF(L13="", "", 1 + MROUND(IFERROR(MINIFS(OFFSET(L13, -1, 0, -$B14, 1), OFFSET(L13, -1, 0, -$B14, 1), ">0"), L13) + (LN(1 + $Z14) ^ U$2) * U$3, 1)) | M14: =IF(M13="", "", 1 + MROUND(IFERROR(MINIFS(OFFSET(M13, -1, 0, -$B14, 1), OFFSET(M13, -1, 0, -$B14, 1), ">0"), M13) + (LN(1 + $Z14) ^ V$2) * V$3, 1)) -> 103 | N14: =IF(N13="", "", 1 + MROUND(IFERROR(MINIFS(OFFSET(N13, -1, 0, -$B14, 1), OFFSET(N13, -1, 0, -$B14, 1), ">0"), N13) + (LN(1 + $Z14) ^ W$2) * W$3, 1)) | O14: =IF(O13="", "", 1 + MROUND(IFERROR(MINIFS(OFFSET(O13, -1, 0, -$B14, 1), OFFSET(O13, -1, 0, -$B14, 1), ">0"), O13) + (LN(1 + $Z14) ^ X$2) * X$3, 1)) -> 77 | P14: =L14*$Y$2 -> 0 | Q14: =M14*$Y$2 -> 25.75 | R14: =N14*$Y$2 -> 0 | S14: =O14*$Y$2 -> 19.25 | T14: =mround(B14/10,1)+1 -> 2 | Z14: =((1+average(D14,F14,H14,J14))^(B14-1)-1) -> 0.51106866
A15: Archer | B15: 14 | C15: =C14+D14*C14 -> 282.84737 | D15: 0.05 | E15: =E14+F14*E14 -> 6.4680332 | F15: 0.02 | G15: =G14+H14*G14 -> 188.56491 | H15: 0.05 | I15: =I14+J14*I14 -> 12.936066 | J15: 0.02 | K15: 0 | L15: =IF(L14="", "", 1 + MROUND(IFERROR(MINIFS(OFFSET(L14, -1, 0, -$B15, 1), OFFSET(L14, -1, 0, -$B15, 1), ">0"), L14) + (LN(1 + $Z15) ^ U$2) * U$3, 1)) | M15: =IF(M14="", "", 1 + MROUND(IFERROR(MINIFS(OFFSET(M14, -1, 0, -$B15, 1), OFFSET(M14, -1, 0, -$B15, 1), ">0"), M14) + (LN(1 + $Z15) ^ V$2) * V$3, 1)) -> 115 | N15: =IF(N14="", "", 1 + MROUND(IFERROR(MINIFS(OFFSET(N14, -1, 0, -$B15, 1), OFFSET(N14, -1, 0, -$B15, 1), ">0"), N14) + (LN(1 + $Z15) ^ W$2) * W$3, 1)) | O15: =IF(O14="", "", 1 + MROUND(IFERROR(MINIFS(OFFSET(O14, -1, 0, -$B15, 1), OFFSET(O14, -1, 0, -$B15, 1), ">0"), O14) + (LN(1 + $Z15) ^ X$2) * X$3, 1)) -> 84 | P15: =L15*$Y$2 -> 0 | Q15: =M15*$Y$2 -> 28.75 | R15: =N15*$Y$2 -> 0 | S15: =O15*$Y$2 -> 21 | T15: =mround(B15/10,1)+1 -> 2 | Z15: =((1+average(D15,F15,H15,J15))^(B15-1)-1) -> 0.56395606
A16: Archer | B16: 15 | C16: =C15+D15*C15 -> 296.98974 | D16: 0.05 | E16: =E15+F15*E15 -> 6.5973938 | F16: 0.02 | G16: =G15+H15*G15 -> 197.99316 | H16: 0.05 | I16: =I15+J15*I15 -> 13.194788 | J16: 0.02 | K16: 0 | L16: =IF(L15="", "", 1 + MROUND(IFERROR(MINIFS(OFFSET(L15, -1, 0, -$B16, 1), OFFSET(L15, -1, 0, -$B16, 1), ">0"), L15) + (LN(1 + $Z16) ^ U$2) * U$3, 1)) | M16: =IF(M15="", "", 1 + MROUND(IFERROR(MINIFS(OFFSET(M15, -1, 0, -$B16, 1), OFFSET(M15, -1, 0, -$B16, 1), ">0"), M15) + (LN(1 + $Z16) ^ V$2) * V$3, 1)) -> 128 | N16: =IF(N15="", "", 1 + MROUND(IFERROR(MINIFS(OFFSET(N15, -1, 0, -$B16, 1), OFFSET(N15, -1, 0, -$B16, 1), ">0"), N15) + (LN(1 + $Z16) ^ W$2) * W$3, 1)) | O16: =IF(O15="", "", 1 + MROUND(IFERROR(MINIFS(OFFSET(O15, -1, 0, -$B16, 1), OFFSET(O15, -1, 0, -$B16, 1), ">0"), O15) + (LN(1 + $Z16) ^ X$2) * X$3, 1)) -> 91 | P16: =L16*$Y$2 -> 0 | Q16: =M16*$Y$2 -> 32 | R16: =N16*$Y$2 -> 0 | S16: =O16*$Y$2 -> 22.75 | T16: =mround(B16/10,1)+1 -> 3 | Z16: =((1+average(D16,F16,H16,J16))^(B16-1)-1) -> 0.61869452
A17: Archer | B17: 16 | C17: =C16+D16*C16 -> 311.83923 | D17: 0.05 | E17: =E16+F16*E16 -> 6.7293417 | F17: 0.02 | G17: =G16+H16*G16 -> 207.89282 | H17: 0.05 | I17: =I16+J16*I16 -> 13.458683 | J17: 0.02 | K17: 0 | L17: =IF(L16="", "", 1 + MROUND(IFERROR(MINIFS(OFFSET(L16, -1, 0, -$B17, 1), OFFSET(L16, -1, 0, -$B17, 1), ">0"), L16) + (LN(1 + $Z17) ^ U$2) * U$3, 1)) | M17: =IF(M16="", "", 1 + MROUND(IFERROR(MINIFS(OFFSET(M16, -1, 0, -$B17, 1), OFFSET(M16, -1, 0, -$B17, 1), ">0"), M16) + (LN(1 + $Z17) ^ V$2) * V$3, 1)) -> 142 | N17: =IF(N16="", "", 1 + MROUND(IFERROR(MINIFS(OFFSET(N16, -1, 0, -$B17, 1), OFFSET(N16, -1, 0, -$B17, 1), ">0"), N16) + (LN(1 + $Z17) ^ W$2) * W$3, 1)) | O17: =IF(O16="", "", 1 + MROUND(IFERROR(MINIFS(OFFSET(O16, -1, 0, -$B17, 1), OFFSET(O16, -1, 0, -$B17, 1), ">0"), O16) + (LN(1 + $Z17) ^ X$2) * X$3, 1)) -> 98 | P17: =L17*$Y$2 -> 0 | Q17: =M17*$Y$2 -> 35.5 | R17: =N17*$Y$2 -> 0 | S17: =O17*$Y$2 -> 24.5 | T17: =mround(B17/10,1)+1 -> 3 | Z17: =((1+average(D17,F17,H17,J17))^(B17-1)-1) -> 0.67534883
... A101: Archer | B101: 100 | C101: =C100+D100*C100 -> 18785.894 | D101: 0.05 | E101: =E100+F100*E100 -> 35.512971 | F101: 0.02 | G101: =G100+H100*G100 -> 12523.929 | H101: 0.05 | I101: =I100+J100*I100 -> 71.025942 | J101: 0.02 | K101: 0 | L101: =IF(L100="", "", 1 + MROUND(IFERROR(MINIFS(OFFSET(L100, -1, 0, -$B101, 1), OFFSET(L100, -1, 0, -$B101, 1), ">0"), L100) + (LN(1 + $Z101) ^ U$2) * U$3, 1)) | M101: =IF(M100="", "", 1 + MROUND(IFERROR(MINIFS(OFFSET(M100, -1, 0, -$B101, 1), OFFSET(M100, -1, 0, -$B101, 1), ">0"), M100) + (LN(1 + $Z101) ^ V$2) * V$3, 1)) -> 2874 | N101: =IF(N100="", "", 1 + MROUND(IFERROR(MINIFS(OFFSET(N100, -1, 0, -$B101, 1), OFFSET(N100, -1, 0, -$B101, 1), ">0"), N100) + (LN(1 + $Z101) ^ W$2) * W$3, 1)) | O101: =IF(O100="", "", 1 + MROUND(IFERROR(MINIFS(OFFSET(O100, -1, 0, -$B101, 1), OFFSET(O100, -1, 0, -$B101, 1), ">0"), O100) + (LN(1 + $Z101) ^ X$2) * X$3, 1)) -> 1508 | P101: =L101*$Y$2 -> 0 | Q101: =M101*$Y$2 -> 718.5 | R101: =N101*$Y$2 -> 0 | S101: =O101*$Y$2 -> 377 | T101: =mround(B101/10,1)+1 -> 11 | Z101: =((1+average(D101,F101,H101,J101))^(B101-1)-1) -> 29.136626
A102: Archer | B102: 101 | C102: =C101+D101*C101 -> 19725.189 | D102: 0.05 | E102: =E101+F101*E101 -> 36.223231 | F102: 0.02 | G102: =G101+H101*G101 -> 13150.126 | H102: 0.05 | I102: =I101+J101*I101 -> 72.446461 | J102: 0.02 | K102: 0 | L102: =M102*10 -> 29220 | M102: =IF(M101="", "", 1 + MROUND(IFERROR(MINIFS(OFFSET(M101, -1, 0, -$B102, 1), OFFSET(M101, -1, 0, -$B102, 1), ">0"), M101) + (LN(1 + $Z102) ^ V$2) * V$3, 1)) -> 2922 | N102: =IF(N101="", "", 1 + MROUND(IFERROR(MINIFS(OFFSET(N101, -1, 0, -$B102, 1), OFFSET(N101, -1, 0, -$B102, 1), ">0"), N101) + (LN(1 + $Z102) ^ W$2) * W$3, 1)) | O102: =IF(O101="", "", 1 + MROUND(IFERROR(MINIFS(OFFSET(O101, -1, 0, -$B102, 1), OFFSET(O101, -1, 0, -$B102, 1), ">0"), O101) + (LN(1 + $Z102) ^ X$2) * X$3, 1)) -> 1533 | P102: =L102*$Y$2 -> 7305 | Q102: =M102*$Y$2 -> 730.5 | R102: =N102*$Y$2 -> 0 | S102: =O102*$Y$2 -> 383.25 | T102: =mround(B102/10,1)+1 -> 11 | Z102: =((1+average(D102,F102,H102,J102))^(B102-1)-1) -> 30.191408
A103: Archer | B103: 102 | C103: =C102+D102*C102 -> 20711.448 | D103: 0.05 | E103: =E102+F102*E102 -> 36.947695 | F103: 0.02 | G103: =G102+H102*G102 -> 13807.632 | H103: 0.05 | I103: =I102+J102*I102 -> 73.89539 | J103: 0.02 | K103: 0 | L103: =IF(L102="", "", 1 + MROUND(IFERROR(MINIFS(OFFSET(L102, -1, 0, -$B103, 1), OFFSET(L102, -1, 0, -$B103, 1), ">0"), L102) + (LN(1 + $Z103) ^ U$2) * U$3, 1)) -> 29819 | M103: =IF(M102="", "", 1 + MROUND(IFERROR(MINIFS(OFFSET(M102, -1, 0, -$B103, 1), OFFSET(M102, -1, 0, -$B103, 1), ">0"), M102) + (LN(1 + $Z103) ^ V$2) * V$3, 1)) -> 2971 | N103: =IF(N102="", "", 1 + MROUND(IFERROR(MINIFS(OFFSET(N102, -1, 0, -$B103, 1), OFFSET(N102, -1, 0, -$B103, 1), ">0"), N102) + (LN(1 + $Z103) ^ W$2) * W$3, 1)) | O103: =IF(O102="", "", 1 + MROUND(IFERROR(MINIFS(OFFSET(O102, -1, 0, -$B103, 1), OFFSET(O102, -1, 0, -$B103, 1), ">0"), O102) + (LN(1 + $Z103) ^ X$2) * X$3, 1)) -> 1558 | P103: =L103*$Y$2 -> 7454.75 | Q103: =M103*$Y$2 -> 742.75 | R103: =N103*$Y$2 -> 0 | S103: =O103*$Y$2 -> 389.5 | T103: =mround(B103/10,1)+1 -> 11 | Z103: =((1+average(D103,F103,H103,J103))^(B103-1)-1) -> 31.283107
A104: Archer | B104: 103 | C104: =C103+D103*C103 -> 21747.021 | D104: 0.05 | E104: =E103+F103*E103 -> 37.686649 | F104: 0.02 | G104: =G103+H103*G103 -> 14498.014 | H104: 0.05 | I104: =I103+J103*I103 -> 75.373298 | J104: 0.02 | K104: 0 | L104: =IF(L103="", "", 1 + MROUND(IFERROR(MINIFS(OFFSET(L103, -1, 0, -$B104, 1), OFFSET(L103, -1, 0, -$B104, 1), ">0"), L103) + (LN(1 + $Z104) ^ U$2) * U$3, 1)) -> 30422 | M104: =IF(M103="", "", 1 + MROUND(IFERROR(MINIFS(OFFSET(M103, -1, 0, -$B104, 1), OFFSET(M103, -1, 0, -$B104, 1), ">0"), M103) + (LN(1 + $Z104) ^ V$2) * V$3, 1)) -> 3020 | N104: =IF(N103="", "", 1 + MROUND(IFERROR(MINIFS(OFFSET(N103, -1, 0, -$B104, 1), OFFSET(N103, -1, 0, -$B104, 1), ">0"), N103) + (LN(1 + $Z104) ^ W$2) * W$3, 1)) | O104: =IF(O103="", "", 1 + MROUND(IFERROR(MINIFS(OFFSET(O103, -1, 0, -$B104, 1), OFFSET(O103, -1, 0, -$B104, 1), ">0"), O103) + (LN(1 + $Z104) ^ X$2) * X$3, 1)) -> 1583 | P104: =L104*$Y$2 -> 7605.5 | Q104: =M104*$Y$2 -> 755 | R104: =N104*$Y$2 -> 0 | S104: =O104*$Y$2 -> 395.75 | T104: =mround(B104/10,1)+1 -> 11 | Z104: =((1+average(D104,F104,H104,J104))^(B104-1)-1) -> 32.413016
A105: Archer | B105: 104 | C105: =C104+D104*C104 -> 22834.372 | D105: 0.05 | E105: =E104+F104*E104 -> 38.440382 | F105: 0.02 | G105: =G104+H104*G104 -> 15222.914 | H105: 0.05 | I105: =I104+J104*I104 -> 76.880764 | J105: 0.02 | K105: 0 | L105: =IF(L104="", "", 1 + MROUND(IFERROR(MINIFS(OFFSET(L104, -1, 0, -$B105, 1), OFFSET(L104, -1, 0, -$B105, 1), ">0"), L104) + (LN(1 + $Z105) ^ U$2) * U$3, 1)) -> 31029 | M105: =IF(M104="", "", 1 + MROUND(IFERROR(MINIFS(OFFSET(M104, -1, 0, -$B105, 1), OFFSET(M104, -1, 0, -$B105, 1), ">0"), M104) + (LN(1 + $Z105) ^ V$2) * V$3, 1)) -> 3069 | N105: =IF(N104="", "", 1 + MROUND(IFERROR(MINIFS(OFFSET(N104, -1, 0, -$B105, 1), OFFSET(N104, -1, 0, -$B105, 1), ">0"), N104) + (LN(1 + $Z105) ^ W$2) * W$3, 1)) | O105: =IF(O104="", "", 1 + MROUND(IFERROR(MINIFS(OFFSET(O104, -1, 0, -$B105, 1), OFFSET(O104, -1, 0, -$B105, 1), ">0"), O104) + (LN(1 + $Z105) ^ X$2) * X$3, 1)) -> 1608 | P105: =L105*$Y$2 -> 7757.25 | Q105: =M105*$Y$2 -> 767.25 | R105: =N105*$Y$2 -> 0 | S105: =O105*$Y$2 -> 402 | T105: =mround(B105/10,1)+1 -> 11 | Z105: =((1+average(D105,F105,H105,J105))^(B105-1)-1) -> 33.582472
A106: Archer | B106: 105 | C106: =C105+D105*C105 -> 23976.09 | D106: 0.05 | E106: =E105+F105*E105 -> 39.20919 | F106: 0.02 | G106: =G105+H105*G105 -> 15984.06 | H106: 0.05 | I106: =I105+J105*I105 -> 78.418379 | J106: 0.02 | K106: 0 | L106: =IF(L105="", "", 1 + MROUND(IFERROR(MINIFS(OFFSET(L105, -1, 0, -$B106, 1), OFFSET(L105, -1, 0, -$B106, 1), ">0"), L105) + (LN(1 + $Z106) ^ U$2) * U$3, 1)) -> 31640 | M106: =IF(M105="", "", 1 + MROUND(IFERROR(MINIFS(OFFSET(M105, -1, 0, -$B106, 1), OFFSET(M105, -1, 0, -$B106, 1), ">0"), M105) + (LN(1 + $Z106) ^ V$2) * V$3, 1)) -> 3119 | N106: =IF(N105="", "", 1 + MROUND(IFERROR(MINIFS(OFFSET(N105, -1, 0, -$B106, 1), OFFSET(N105, -1, 0, -$B106, 1), ">0"), N105) + (LN(1 + $Z106) ^ W$2) * W$3, 1)) | O106: =IF(O105="", "", 1 + MROUND(IFERROR(MINIFS(OFFSET(O105, -1, 0, -$B106, 1), OFFSET(O105, -1, 0, -$B106, 1), ">0"), O105) + (LN(1 + $Z106) ^ X$2) * X$3, 1)) -> 1633 | P106: =L106*$Y$2 -> 7910 | Q106: =M106*$Y$2 -> 779.75 | R106: =N106*$Y$2 -> 0 | S106: =O106*$Y$2 -> 408.25 | T106: =mround(B106/10,1)+1 -> 12 | Z106: =((1+average(D106,F106,H106,J106))^(B106-1)-1) -> 34.792858
A107: Archer | B107: 106 | C107: =C106+D106*C106 -> 25174.895 | D107: 0.05 | E107: =E106+F106*E106 -> 39.993374 | F107: 0.02 | G107: =G106+H106*G106 -> 16783.263 | H107: 0.05 | I107: =I106+J106*I106 -> 79.986747 | J107: 0.02 | K107: 0 | L107: =IF(L106="", "", 1 + MROUND(IFERROR(MINIFS(OFFSET(L106, -1, 0, -$B107, 1), OFFSET(L106, -1, 0, -$B107, 1), ">0"), L106) + (LN(1 + $Z107) ^ U$2) * U$3, 1)) -> 32255 | M107: =IF(M106="", "", 1 + MROUND(IFERROR(MINIFS(OFFSET(M106, -1, 0, -$B107, 1), OFFSET(M106, -1, 0, -$B107, 1), ">0"), M106) + (LN(1 + $Z107) ^ V$2) * V$3, 1)) -> 3169 | N107: =IF(N106="", "", 1 + MROUND(IFERROR(MINIFS(OFFSET(N106, -1, 0, -$B107, 1), OFFSET(N106, -1, 0, -$B107, 1), ">0"), N106) + (LN(1 + $Z107) ^ W$2) * W$3, 1)) | O107: =IF(O106="", "", 1 + MROUND(IFERROR(MINIFS(OFFSET(O106, -1, 0, -$B107, 1), OFFSET(O106, -1, 0, -$B107, 1), ">0"), O106) + (LN(1 + $Z107) ^ X$2) * X$3, 1)) -> 1659 | P107: =L107*$Y$2 -> 8063.75 | Q107: =M107*$Y$2 -> 792.25 | R107: =N107*$Y$2 -> 0 | S107: =O107*$Y$2 -> 414.75 | T107: =mround(B107/10,1)+1 -> 12 | Z107: =((1+average(D107,F107,H107,J107))^(B107-1)-1) -> 36.045608
A108: Archer | B108: 107 | C108: =C107+D107*C107 -> 26433.639 | D108: 0.05 | E108: =E107+F107*E107 -> 40.793241 | F108: 0.02 | G108: =G107+H107*G107 -> 17622.426 | H108: 0.05 | I108: =I107+J107*I107 -> 81.586482 | J108: 0.02 | K108: 0 | L108: =IF(L107="", "", 1 + MROUND(IFERROR(MINIFS(OFFSET(L107, -1, 0, -$B108, 1), OFFSET(L107, -1, 0, -$B108, 1), ">0"), L107) + (LN(1 + $Z108) ^ U$2) * U$3, 1)) -> 32874 | M108: =IF(M107="", "", 1 + MROUND(IFERROR(MINIFS(OFFSET(M107, -1, 0, -$B108, 1), OFFSET(M107, -1, 0, -$B108, 1), ">0"), M107) + (LN(1 + $Z108) ^ V$2) * V$3, 1)) -> 3219 | N108: =IF(N107="", "", 1 + MROUND(IFERROR(MINIFS(OFFSET(N107, -1, 0, -$B108, 1), OFFSET(N107, -1, 0, -$B108, 1), ">0"), N107) + (LN(1 + $Z108) ^ W$2) * W$3, 1)) | O108: =IF(O107="", "", 1 + MROUND(IFERROR(MINIFS(OFFSET(O107, -1, 0, -$B108, 1), OFFSET(O107, -1, 0, -$B108, 1), ">0"), O107) + (LN(1 + $Z108) ^ X$2) * X$3, 1)) -> 1685 | P108: =L108*$Y$2 -> 8218.5 | Q108: =M108*$Y$2 -> 804.75 | R108: =N108*$Y$2 -> 0 | S108: =O108*$Y$2 -> 421.25 | T108: =mround(B108/10,1)+1 -> 12 | Z108: =((1+average(D108,F108,H108,J108))^(B108-1)-1) -> 37.342204
A109: Archer | B109: 108 | C109: =C108+D108*C108 -> 27755.321 | D109: 0.05 | E109: =E108+F108*E108 -> 41.609106 | F109: 0.02 | G109: =G108+H108*G108 -> 18503.548 | H109: 0.05 | I109: =I108+J108*I108 -> 83.218212 | J109: 0.02 | K109: 0 | L109: =IF(L108="", "", 1 + MROUND(IFERROR(MINIFS(OFFSET(L108, -1, 0, -$B109, 1), OFFSET(L108, -1, 0, -$B109, 1), ">0"), L108) + (LN(1 + $Z109) ^ U$2) * U$3, 1)) -> 33497 | M109: =IF(M108="", "", 1 + MROUND(IFERROR(MINIFS(OFFSET(M108, -1, 0, -$B109, 1), OFFSET(M108, -1, 0, -$B109, 1), ">0"), M108) + (LN(1 + $Z109) ^ V$2) * V$3, 1)) -> 3270 | N109: =IF(N108="", "", 1 + MROUND(IFERROR(MINIFS(OFFSET(N108, -1, 0, -$B109, 1), OFFSET(N108, -1, 0, -$B109, 1), ">0"), N108) + (LN(1 + $Z109) ^ W$2) * W$3, 1)) | O109: =IF(O108="", "", 1 + MROUND(IFERROR(MINIFS(OFFSET(O108, -1, 0, -$B109, 1), OFFSET(O108, -1, 0, -$B109, 1), ">0"), O108) + (LN(1 + $Z109) ^ X$2) * X$3, 1)) -> 1711 | P109: =L109*$Y$2 -> 8374.25 | Q109: =M109*$Y$2 -> 817.5 | R109: =N109*$Y$2 -> 0 | S109: =O109*$Y$2 -> 427.75 | T109: =mround(B109/10,1)+1 -> 12 | Z109: =((1+average(D109,F109,H109,J109))^(B109-1)-1) -> 38.684182
A110: Archer | B110: 109 | C110: =C109+D109*C109 -> 29143.087 | D110: 0.05 | E110: =E109+F109*E109 -> 42.441288 | F110: 0.02 | G110: =G109+H109*G109 -> 19428.725 | H110: 0.05 | I110: =I109+J109*I109 -> 84.882576 | J110: 0.02 | K110: 0 | L110: =IF(L109="", "", 1 + MROUND(IFERROR(MINIFS(OFFSET(L109, -1, 0, -$B110, 1), OFFSET(L109, -1, 0, -$B110, 1), ">0"), L109) + (LN(1 + $Z110) ^ U$2) * U$3, 1)) -> 34125 | M110: =IF(M109="", "", 1 + MROUND(IFERROR(MINIFS(OFFSET(M109, -1, 0, -$B110, 1), OFFSET(M109, -1, 0, -$B110, 1), ">0"), M109) + (LN(1 + $Z110) ^ V$2) * V$3, 1)) -> 3321 | N110: =IF(N109="", "", 1 + MROUND(IFERROR(MINIFS(OFFSET(N109, -1, 0, -$B110, 1), OFFSET(N109, -1, 0, -$B110, 1), ">0"), N109) + (LN(1 + $Z110) ^ W$2) * W$3, 1)) | O110: =IF(O109="", "", 1 + MROUND(IFERROR(MINIFS(OFFSET(O109, -1, 0, -$B110, 1), OFFSET(O109, -1, 0, -$B110, 1), ">0"), O109) + (LN(1 + $Z110) ^ X$2) * X$3, 1)) -> 1737 | P110: =L110*$Y$2 -> 8531.25 | Q110: =M110*$Y$2 -> 830.25 | R110: =N110*$Y$2 -> 0 | S110: =O110*$Y$2 -> 434.25 | T110: =mround(B110/10,1)+1 -> 12 | Z110: =((1+average(D110,F110,H110,J110))^(B110-1)-1) -> 40.073128
A111: Archer | B111: 110 | C111: =C110+D110*C110 -> 30600.242 | D111: 0.05 | E111: =E110+F110*E110 -> 43.290114 | F111: 0.02 | G111: =G110+H110*G110 -> 20400.161 | H111: 0.05 | I111: =I110+J110*I110 -> 86.580227 | J111: 0.02 | K111: 0 | L111: =IF(L110="", "", 1 + MROUND(IFERROR(MINIFS(OFFSET(L110, -1, 0, -$B111, 1), OFFSET(L110, -1, 0, -$B111, 1), ">0"), L110) + (LN(1 + $Z111) ^ U$2) * U$3, 1)) -> 34757 | M111: =IF(M110="", "", 1 + MROUND(IFERROR(MINIFS(OFFSET(M110, -1, 0, -$B111, 1), OFFSET(M110, -1, 0, -$B111, 1), ">0"), M110) + (LN(1 + $Z111) ^ V$2) * V$3, 1)) -> 3372 | N111: =IF(N110="", "", 1 + MROUND(IFERROR(MINIFS(OFFSET(N110, -1, 0, -$B111, 1), OFFSET(N110, -1, 0, -$B111, 1), ">0"), N110) + (LN(1 + $Z111) ^ W$2) * W$3, 1)) | O111: =IF(O110="", "", 1 + MROUND(IFERROR(MINIFS(OFFSET(O110, -1, 0, -$B111, 1), OFFSET(O110, -1, 0, -$B111, 1), ">0"), O110) + (LN(1 + $Z111) ^ X$2) * X$3, 1)) -> 1763 | P111: =L111*$Y$2 -> 8689.25 | Q111: =M111*$Y$2 -> 843 | R111: =N111*$Y$2 -> 0 | S111: =O111*$Y$2 -> 440.75 | T111: =mround(B111/10,1)+1 -> 12 | Z111: =((1+average(D111,F111,H111,J111))^(B111-1)-1) -> 41.510687
A112: Archer | B112: 111 | C112: =C111+D111*C111 -> 32130.254 | D112: 0.05 | E112: =E111+F111*E111 -> 44.155916 | F112: 0.02 | G112: =G111+H111*G111 -> 21420.169 | H112: 0.05 | I112: =I111+J111*I111 -> 88.311832 | J112: 0.02 | K112: 0 | L112: =IF(L111="", "", 1 + MROUND(IFERROR(MINIFS(OFFSET(L111, -1, 0, -$B112, 1), OFFSET(L111, -1, 0, -$B112, 1), ">0"), L111) + (LN(1 + $Z112) ^ U$2) * U$3, 1)) -> 35393 | M112: =IF(M111="", "", 1 + MROUND(IFERROR(MINIFS(OFFSET(M111, -1, 0, -$B112, 1), OFFSET(M111, -1, 0, -$B112, 1), ">0"), M111) + (LN(1 + $Z112) ^ V$2) * V$3, 1)) -> 3424 | N112: =IF(N111="", "", 1 + MROUND(IFERROR(MINIFS(OFFSET(N111, -1, 0, -$B112, 1), OFFSET(N111, -1, 0, -$B112, 1), ">0"), N111) + (LN(1 + $Z112) ^ W$2) * W$3, 1)) | O112: =IF(O111="", "", 1 + MROUND(IFERROR(MINIFS(OFFSET(O111, -1, 0, -$B112, 1), OFFSET(O111, -1, 0, -$B112, 1), ">0"), O111) + (LN(1 + $Z112) ^ X$2) * X$3, 1)) -> 1789 | P112: =L112*$Y$2 -> 8848.25 | Q112: =M112*$Y$2 -> 856 | R112: =N112*$Y$2 -> 0 | S112: =O112*$Y$2 -> 447.25 | T112: =mround(B112/10,1)+1 -> 12 | Z112: =((1+average(D112,F112,H112,J112))^(B112-1)-1) -> 42.998561
A113: Archer | B113: 112 | C113: =C112+D112*C112 -> 33736.767 | D113: 0.05 | E113: =E112+F112*E112 -> 45.039034 | F113: 0.02 | G113: =G112+H112*G112 -> 22491.178 | H113: 0.05 | I113: =I112+J112*I112 -> 90.078069 | J113: 0.02 | K113: 0 | L113: =IF(L112="", "", 1 + MROUND(IFERROR(MINIFS(OFFSET(L112, -1, 0, -$B113, 1), OFFSET(L112, -1, 0, -$B113, 1), ">0"), L112) + (LN(1 + $Z113) ^ U$2) * U$3, 1)) -> 36033 | M113: =IF(M112="", "", 1 + MROUND(IFERROR(MINIFS(OFFSET(M112, -1, 0, -$B113, 1), OFFSET(M112, -1, 0, -$B113, 1), ">0"), M112) + (LN(1 + $Z113) ^ V$2) * V$3, 1)) -> 3476 | N113: =IF(N112="", "", 1 + MROUND(IFERROR(MINIFS(OFFSET(N112, -1, 0, -$B113, 1), OFFSET(N112, -1, 0, -$B113, 1), ">0"), N112) + (LN(1 + $Z113) ^ W$2) * W$3, 1)) | O113: =IF(O112="", "", 1 + MROUND(IFERROR(MINIFS(OFFSET(O112, -1, 0, -$B113, 1), OFFSET(O112, -1, 0, -$B113, 1), ">0"), O112) + (LN(1 + $Z113) ^ X$2) * X$3, 1)) -> 1816 | P113: =L113*$Y$2 -> 9008.25 | Q113: =M113*$Y$2 -> 869 | R113: =N113*$Y$2 -> 0 | S113: =O113*$Y$2 -> 454 | T113: =mround(B113/10,1)+1 -> 12 | Z113: =((1+average(D113,F113,H113,J113))^(B113-1)-1) -> 44.538511
A114: Archer | B114: 113 | C114: =C113+D113*C113 -> 35423.605 | D114: 0.05 | E114: =E113+F113*E113 -> 45.939815 | F114: 0.02 | G114: =G113+H113*G113 -> 23615.737 | H114: 0.05 | I114: =I113+J113*I113 -> 91.87963 | J114: 0.02 | K114: 0 | L114: =IF(L113="", "", 1 + MROUND(IFERROR(MINIFS(OFFSET(L113, -1, 0, -$B114, 1), OFFSET(L113, -1, 0, -$B114, 1), ">0"), L113) + (LN(1 + $Z114) ^ U$2) * U$3, 1)) -> 36677 | M114: =IF(M113="", "", 1 + MROUND(IFERROR(MINIFS(OFFSET(M113, -1, 0, -$B114, 1), OFFSET(M113, -1, 0, -$B114, 1), ">0"), M113) + (LN(1 + $Z114) ^ V$2) * V$3, 1)) -> 3528 | N114: =IF(N113="", "", 1 + MROUND(IFERROR(MINIFS(OFFSET(N113, -1, 0, -$B114, 1), OFFSET(N113, -1, 0, -$B114, 1), ">0"), N113) + (LN(1 + $Z114) ^ W$2) * W$3, 1)) | O114: =IF(O113="", "", 1 + MROUND(IFERROR(MINIFS(OFFSET(O113, -1, 0, -$B114, 1), OFFSET(O113, -1, 0, -$B114, 1), ">0"), O113) + (LN(1 + $Z114) ^ X$2) * X$3, 1)) -> 1843 | P114: =L114*$Y$2 -> 9169.25 | Q114: =M114*$Y$2 -> 882 | R114: =N114*$Y$2 -> 0 | S114: =O114*$Y$2 -> 460.75 | T114: =mround(B114/10,1)+1 -> 12 | Z114: =((1+average(D114,F114,H114,J114))^(B114-1)-1) -> 46.132359
... A200: Archer | B200: 199 | C200: =C199+D199*C199 -> 2352732.1 | D200: 0.05 | E200: =E199+F199*E199 -> 252.23422 | F200: 0.02 | G200: =G199+H199*G199 -> 1568488.1 | H200: 0.05 | I200: =I199+J199*I199 -> 504.46845 | J200: 0.02 | K200: 0 | L200: =IF(L199="", "", 1 + MROUND(IFERROR(MINIFS(OFFSET(L199, -1, 0, -$B200, 1), OFFSET(L199, -1, 0, -$B200, 1), ">0"), L199) + (LN(1 + $Z200) ^ U$2) * U$3, 1)) -> 106119 | M200: =IF(M199="", "", 1 + MROUND(IFERROR(MINIFS(OFFSET(M199, -1, 0, -$B200, 1), OFFSET(M199, -1, 0, -$B200, 1), ">0"), M199) + (LN(1 + $Z200) ^ V$2) * V$3, 1)) -> 9164 | N200: =IF(N199="", "", 1 + MROUND(IFERROR(MINIFS(OFFSET(N199, -1, 0, -$B200, 1), OFFSET(N199, -1, 0, -$B200, 1), ">0"), N199) + (LN(1 + $Z200) ^ W$2) * W$3, 1)) | O200: =IF(O199="", "", 1 + MROUND(IFERROR(MINIFS(OFFSET(O199, -1, 0, -$B200, 1), OFFSET(O199, -1, 0, -$B200, 1), ">0"), O199) + (LN(1 + $Z200) ^ X$2) * X$3, 1)) -> 4704 | P200: =L200*$Y$2 -> 26529.75 | Q200: =M200*$Y$2 -> 2291 | R200: =N200*$Y$2 -> 0 | S200: =O200*$Y$2 -> 1176 | T200: =mround(B200/10,1)+1 -> 21 | Z200: =((1+average(D200,F200,H200,J200))^(B200-1)-1) -> 907.21623
A201: Archer | B201: 200 | C201: =C200+D200*C200 -> 2470368.7 | D201: 0.05 | E201: =E200+F200*E200 -> 257.27891 | F201: 0.02 | G201: =G200+H200*G200 -> 1646912.5 | H201: 0.05 | I201: =I200+J200*I200 -> 514.55782 | J201: 0.02 | K201: 0 | L201: =IF(L200="", "", 1 + MROUND(IFERROR(MINIFS(OFFSET(L200, -1, 0, -$B201, 1), OFFSET(L200, -1, 0, -$B201, 1), ">0"), L200) + (LN(1 + $Z201) ^ U$2) * U$3, 1)) -> 107081 | M201: =IF(M200="", "", 1 + MROUND(IFERROR(MINIFS(OFFSET(M200, -1, 0, -$B201, 1), OFFSET(M200, -1, 0, -$B201, 1), ">0"), M200) + (LN(1 + $Z201) ^ V$2) * V$3, 1)) -> 9242 | N201: =M201/10 -> 924.2 | O201: =IF(O200="", "", 1 + MROUND(IFERROR(MINIFS(OFFSET(O200, -1, 0, -$B201, 1), OFFSET(O200, -1, 0, -$B201, 1), ">0"), O200) + (LN(1 + $Z201) ^ X$2) * X$3, 1)) -> 4743 | P201: =L201*$Y$2 -> 26770.25 | Q201: =M201*$Y$2 -> 2310.5 | R201: =N201*$Y$2 -> 231.05 | S201: =O201*$Y$2 -> 1185.75 | T201: =mround(B201/10,1)+1 -> 21 | Z201: =((1+average(D201,F201,H201,J201))^(B201-1)-1) -> 939.0038
A202: Archer | B202: 201 | C202: =C201+D201*C201 -> 2593887.1 | D202: 0.05 | E202: =E201+F201*E201 -> 262.42449 | F202: 0.02 | G202: =G201+H201*G201 -> 1729258.1 | H202: 0.05 | I202: =I201+J201*I201 -> 524.84897 | J202: 0.02 | K202: 0 | L202: =IF(L201="", "", 1 + MROUND(IFERROR(MINIFS(OFFSET(L201, -1, 0, -$B202, 1), OFFSET(L201, -1, 0, -$B202, 1), ">0"), L201) + (LN(1 + $Z202) ^ U$2) * U$3, 1)) -> 108046 | M202: =IF(M201="", "", 1 + MROUND(IFERROR(MINIFS(OFFSET(M201, -1, 0, -$B202, 1), OFFSET(M201, -1, 0, -$B202, 1), ">0"), M201) + (LN(1 + $Z202) ^ V$2) * V$3, 1)) -> 9320 | N202: =IF(N201="", "", 1 + MROUND(IFERROR(MINIFS(OFFSET(N201, -1, 0, -$B202, 1), OFFSET(N201, -1, 0, -$B202, 1), ">0"), N201) + (LN(1 + $Z202) ^ W$2) * W$3, 1)) -> 964 | O202: =IF(O201="", "", 1 + MROUND(IFERROR(MINIFS(OFFSET(O201, -1, 0, -$B202, 1), OFFSET(O201, -1, 0, -$B202, 1), ">0"), O201) + (LN(1 + $Z202) ^ X$2) * X$3, 1)) -> 4783 | P202: =L202*$Y$2 -> 27011.5 | Q202: =M202*$Y$2 -> 2330 | R202: =N202*$Y$2 -> 241 | S202: =O202*$Y$2 -> 1195.75 | T202: =mround(B202/10,1)+1 -> 21 | Z202: =((1+average(D202,F202,H202,J202))^(B202-1)-1) -> 971.90393
A203: Archer | B203: 202 | C203: =C202+D202*C202 -> 2723581.5 | D203: 0.05 | E203: =E202+F202*E202 -> 267.67298 | F203: 0.02 | G203: =G202+H202*G202 -> 1815721 | H203: 0.05 | I203: =I202+J202*I202 -> 535.34595 | J203: 0.02 | K203: 0 | L203: =IF(L202="", "", 1 + MROUND(IFERROR(MINIFS(OFFSET(L202, -1, 0, -$B203, 1), OFFSET(L202, -1, 0, -$B203, 1), ">0"), L202) + (LN(1 + $Z203) ^ U$2) * U$3, 1)) -> 109015 | M203: =IF(M202="", "", 1 + MROUND(IFERROR(MINIFS(OFFSET(M202, -1, 0, -$B203, 1), OFFSET(M202, -1, 0, -$B203, 1), ">0"), M202) + (LN(1 + $Z203) ^ V$2) * V$3, 1)) -> 9398 | N203: =IF(N202="", "", 1 + MROUND(IFERROR(MINIFS(OFFSET(N202, -1, 0, -$B203, 1), OFFSET(N202, -1, 0, -$B203, 1), ">0"), N202) + (LN(1 + $Z203) ^ W$2) * W$3, 1)) -> 1004 | O203: =IF(O202="", "", 1 + MROUND(IFERROR(MINIFS(OFFSET(O202, -1, 0, -$B203, 1), OFFSET(O202, -1, 0, -$B203, 1), ">0"), O202) + (LN(1 + $Z203) ^ X$2) * X$3, 1)) -> 4823 | P203: =L203*$Y$2 -> 27253.75 | Q203: =M203*$Y$2 -> 2349.5 | R203: =N203*$Y$2 -> 251 | S203: =O203*$Y$2 -> 1205.75 | T203: =mround(B203/10,1)+1 -> 21 | Z203: =((1+average(D203,F203,H203,J203))^(B203-1)-1) -> 1005.9556
A204: Archer | B204: 203 | C204: =C203+D203*C203 -> 2859760.6 | D204: 0.05 | E204: =E203+F203*E203 -> 273.02644 | F204: 0.02 | G204: =G203+H203*G203 -> 1906507 | H204: 0.05 | I204: =I203+J203*I203 -> 546.05287 | J204: 0.02 | K204: 0 | L204: =IF(L203="", "", 1 + MROUND(IFERROR(MINIFS(OFFSET(L203, -1, 0, -$B204, 1), OFFSET(L203, -1, 0, -$B204, 1), ">0"), L203) + (LN(1 + $Z204) ^ U$2) * U$3, 1)) -> 109987 | M204: =IF(M203="", "", 1 + MROUND(IFERROR(MINIFS(OFFSET(M203, -1, 0, -$B204, 1), OFFSET(M203, -1, 0, -$B204, 1), ">0"), M203) + (LN(1 + $Z204) ^ V$2) * V$3, 1)) -> 9477 | N204: =IF(N203="", "", 1 + MROUND(IFERROR(MINIFS(OFFSET(N203, -1, 0, -$B204, 1), OFFSET(N203, -1, 0, -$B204, 1), ">0"), N203) + (LN(1 + $Z204) ^ W$2) * W$3, 1)) -> 1044 | O204: =IF(O203="", "", 1 + MROUND(IFERROR(MINIFS(OFFSET(O203, -1, 0, -$B204, 1), OFFSET(O203, -1, 0, -$B204, 1), ">0"), O203) + (LN(1 + $Z204) ^ X$2) * X$3, 1)) -> 4863 | P204: =L204*$Y$2 -> 27496.75 | Q204: =M204*$Y$2 -> 2369.25 | R204: =N204*$Y$2 -> 261 | S204: =O204*$Y$2 -> 1215.75 | T204: =mround(B204/10,1)+1 -> 21 | Z204: =((1+average(D204,F204,H204,J204))^(B204-1)-1) -> 1041.199
A205: Archer | B205: 204 | C205: =C204+D204*C204 -> 3002748.6 | D205: 0.05 | E205: =E204+F204*E204 -> 278.48696 | F205: 0.02 | G205: =G204+H204*G204 -> 2001832.4 | H205: 0.05 | I205: =I204+J204*I204 -> 556.97393 | J205: 0.02 | K205: 0 | L205: =IF(L204="", "", 1 + MROUND(IFERROR(MINIFS(OFFSET(L204, -1, 0, -$B205, 1), OFFSET(L204, -1, 0, -$B205, 1), ">0"), L204) + (LN(1 + $Z205) ^ U$2) * U$3, 1)) -> 110963 | M205: =IF(M204="", "", 1 + MROUND(IFERROR(MINIFS(OFFSET(M204, -1, 0, -$B205, 1), OFFSET(M204, -1, 0, -$B205, 1), ">0"), M204) + (LN(1 + $Z205) ^ V$2) * V$3, 1)) -> 9556 | N205: =IF(N204="", "", 1 + MROUND(IFERROR(MINIFS(OFFSET(N204, -1, 0, -$B205, 1), OFFSET(N204, -1, 0, -$B205, 1), ">0"), N204) + (LN(1 + $Z205) ^ W$2) * W$3, 1)) -> 1084 | O205: =IF(O204="", "", 1 + MROUND(IFERROR(MINIFS(OFFSET(O204, -1, 0, -$B205, 1), OFFSET(O204, -1, 0, -$B205, 1), ">0"), O204) + (LN(1 + $Z205) ^ X$2) * X$3, 1)) -> 4903 | P205: =L205*$Y$2 -> 27740.75 | Q205: =M205*$Y$2 -> 2389 | R205: =N205*$Y$2 -> 271 | S205: =O205*$Y$2 -> 1225.75 | T205: =mround(B205/10,1)+1 -> 21 | Z205: =((1+average(D205,F205,H205,J205))^(B205-1)-1) -> 1077.676
A206: Archer | B206: 205 | C206: =C205+D205*C205 -> 3152886 | D206: 0.05 | E206: =E205+F205*E205 -> 284.0567 | F206: 0.02 | G206: =G205+H205*G205 -> 2101924 | H206: 0.05 | I206: =I205+J205*I205 -> 568.11341 | J206: 0.02 | K206: 0 | L206: =IF(L205="", "", 1 + MROUND(IFERROR(MINIFS(OFFSET(L205, -1, 0, -$B206, 1), OFFSET(L205, -1, 0, -$B206, 1), ">0"), L205) + (LN(1 + $Z206) ^ U$2) * U$3, 1)) -> 111942 | M206: =IF(M205="", "", 1 + MROUND(IFERROR(MINIFS(OFFSET(M205, -1, 0, -$B206, 1), OFFSET(M205, -1, 0, -$B206, 1), ">0"), M205) + (LN(1 + $Z206) ^ V$2) * V$3, 1)) -> 9635 | N206: =IF(N205="", "", 1 + MROUND(IFERROR(MINIFS(OFFSET(N205, -1, 0, -$B206, 1), OFFSET(N205, -1, 0, -$B206, 1), ">0"), N205) + (LN(1 + $Z206) ^ W$2) * W$3, 1)) -> 1124 | O206: =IF(O205="", "", 1 + MROUND(IFERROR(MINIFS(OFFSET(O205, -1, 0, -$B206, 1), OFFSET(O205, -1, 0, -$B206, 1), ">0"), O205) + (LN(1 + $Z206) ^ X$2) * X$3, 1)) -> 4943 | P206: =L206*$Y$2 -> 27985.5 | Q206: =M206*$Y$2 -> 2408.75 | R206: =N206*$Y$2 -> 281 | S206: =O206*$Y$2 -> 1235.75 | T206: =mround(B206/10,1)+1 -> 22 | Z206: =((1+average(D206,F206,H206,J206))^(B206-1)-1) -> 1115.4296
A207: Archer | B207: 206 | C207: =C206+D206*C206 -> 3310530.3 | D207: 0.05 | E207: =E206+F206*E206 -> 289.73784 | F207: 0.02 | G207: =G206+H206*G206 -> 2207020.2 | H207: 0.05 | I207: =I206+J206*I206 -> 579.47568 | J207: 0.02 | K207: 0 | L207: =IF(L206="", "", 1 + MROUND(IFERROR(MINIFS(OFFSET(L206, -1, 0, -$B207, 1), OFFSET(L206, -1, 0, -$B207, 1), ">0"), L206) + (LN(1 + $Z207) ^ U$2) * U$3, 1)) -> 112924 | M207: =IF(M206="", "", 1 + MROUND(IFERROR(MINIFS(OFFSET(M206, -1, 0, -$B207, 1), OFFSET(M206, -1, 0, -$B207, 1), ">0"), M206) + (LN(1 + $Z207) ^ V$2) * V$3, 1)) -> 9714 | N207: =IF(N206="", "", 1 + MROUND(IFERROR(MINIFS(OFFSET(N206, -1, 0, -$B207, 1), OFFSET(N206, -1, 0, -$B207, 1), ">0"), N206) + (LN(1 + $Z207) ^ W$2) * W$3, 1)) -> 1164 | O207: =IF(O206="", "", 1 + MROUND(IFERROR(MINIFS(OFFSET(O206, -1, 0, -$B207, 1), OFFSET(O206, -1, 0, -$B207, 1), ">0"), O206) + (LN(1 + $Z207) ^ X$2) * X$3, 1)) -> 4983 | P207: =L207*$Y$2 -> 28231 | Q207: =M207*$Y$2 -> 2428.5 | R207: =N207*$Y$2 -> 291 | S207: =O207*$Y$2 -> 1245.75 | T207: =mround(B207/10,1)+1 -> 22 | Z207: =((1+average(D207,F207,H207,J207))^(B207-1)-1) -> 1154.5047
A208: Archer | B208: 207 | C208: =C207+D207*C207 -> 3476056.8 | D208: 0.05 | E208: =E207+F207*E207 -> 295.5326 | F208: 0.02 | G208: =G207+H207*G207 -> 2317371.2 | H208: 0.05 | I208: =I207+J207*I207 -> 591.06519 | J208: 0.02 | K208: 0 | L208: =IF(L207="", "", 1 + MROUND(IFERROR(MINIFS(OFFSET(L207, -1, 0, -$B208, 1), OFFSET(L207, -1, 0, -$B208, 1), ">0"), L207) + (LN(1 + $Z208) ^ U$2) * U$3, 1)) -> 113910 | M208: =IF(M207="", "", 1 + MROUND(IFERROR(MINIFS(OFFSET(M207, -1, 0, -$B208, 1), OFFSET(M207, -1, 0, -$B208, 1), ">0"), M207) + (LN(1 + $Z208) ^ V$2) * V$3, 1)) -> 9794 | N208: =IF(N207="", "", 1 + MROUND(IFERROR(MINIFS(OFFSET(N207, -1, 0, -$B208, 1), OFFSET(N207, -1, 0, -$B208, 1), ">0"), N207) + (LN(1 + $Z208) ^ W$2) * W$3, 1)) -> 1204 | O208: =IF(O207="", "", 1 + MROUND(IFERROR(MINIFS(OFFSET(O207, -1, 0, -$B208, 1), OFFSET(O207, -1, 0, -$B208, 1), ">0"), O207) + (LN(1 + $Z208) ^ X$2) * X$3, 1)) -> 5023 | P208: =L208*$Y$2 -> 28477.5 | Q208: =M208*$Y$2 -> 2448.5 | R208: =N208*$Y$2 -> 301 | S208: =O208*$Y$2 -> 1255.75 | T208: =mround(B208/10,1)+1 -> 22 | Z208: =((1+average(D208,F208,H208,J208))^(B208-1)-1) -> 1194.9473
...
